Workbook

Sheet По порядку
A1: Номер п.п. | B1: Самаса | C1: Подтип | D1: Тип | E1: Шлока
A2: 1 | B2: śrīpatim | C2: ṣaṣṭhī- | D2: tatpuruṣa | E2: 1.1
A3: 2 | B3: śrīvatsāṅkitavakṣasam | C3: samānādhikaraṇa- | D3: bahuvrīhi | E3: 1.1
A4: 3 | B4: śrīvatsāṅkita | C4: tṛtīyā- | D4: tatpuruṣa | E4: 1.1
A5: 4 | B5: śrīvatsa | C5: viśeṣaṇapūrvapadaḥ | D5: karmadhāraya | E5: 1.1
A6: 5 | B6: śrīrāmodantam | C6: ṣaṣṭhī- | D6: tatpuruṣa | E6: 1.1
A7: 6 | B7: śrīrāma | C7: viśeṣaṇapūrvapadaḥ | D7: karmadhāraya | E7: 1.1
A8: 7 | B8: śrīvālmīkiprakīrtitam | C8: tṛtīyā- | D8: tatpuruṣa | E8: 1.1
A9: 8 | B9: śrīvālmīki | C9: viśeṣaṇapūrvapadaḥ | D9: karmadhāraya | E9: 1.1
A10: 9 | B10: kumbhakarṇavibhīṣaṇau | C10: itaretara- | D10: dvandva | E10: 1.2
A11: 10 | B11: āśritavatsalāt | C11: ṣaṣṭhī- | D11: tatpuruṣa | E11: 1.3
A12: 11 | B12: nirdevatvecchayā | C12: dvitīyā- | D12: tatpuruṣa | E12: 1.4
A13: 12 | B13: viṣṇubhaktim | C13: ṣaṣṭhī- | D13: tatpuruṣa | E13: 1.5
... A117: 116 | B117: saṃskārādi | C117: samānādhikaraṇa- | D117: bahuvrīhi | E117: 2.14
A118: 117 | B118: yathāvidhi | D118: avyayībhāva | E118: 2.14
A119: 118 | B119: citrakūṭastham | C119: upapada- | D119: tatpuruṣa | E119: 2.16
A120: 119 | B120: citrakūṭa | C120: viśeṣaṇapūrvapadaḥ | D120: karmadhāraya | E120: 2.16
A121: 120 | B121: cīrajaṭādharam | C121: upapada- | D121: tatpuruṣa | E121: 2.16
A122: 121 | B122: cīrajaṭā | C122: itaretara- | D122: dvandva | E122: 2.16
A123: 122 | B123: vasiṣṭhādyaiḥ | C123: samānādhikaraṇa- | D123: bahuvrīhi | E123: 2.16
A124: 123 | B124: dvijaiḥ | C124: upapada- | D124: tatpuruṣa | E124: 2.16
A125: 124 | B125: dīnamānasaḥ | C125: samānādhikaraṇa- | D125: bahuvrīhi | E125: 2.18
A126: 125 | B126: nandigrāme | C126: ṣaṣṭhī- | D126: tatpuruṣa | E126: 2.18
A127: 126 | B127: vasuṃdharām | C127: upapada- | D127: tatpuruṣa | E127: 2.18
A128: 127 | B128: tatpatnī | C128: ṣaṣṭhī- | D128: tatpuruṣa | E128: 2.19
A129: 128 | B129: daṇḍakāraṇyam | C129: viśeṣaṇapūrvapadaḥ | D129: karmadhāraya | E129: 2.20
A130: 129 | B130: sītālakṣmaṇasaṃyutaḥ | C130: tṛtīyā- | D130: tatpuruṣa | E130: 2.20
... A379: 378 | B379: kapīśvarāḥ | C379: ṣaṣṭhī- | D379: tatpuruṣa | E379: 6.61
A380: 379 | B380: yathārham | D380: avyayībhāva | E380: 6.61
A381: 380 | B381: sraggandhāmbarabhūṣaṇaiḥ | C381: itaretara- | D381: dvandva | E381: 6.61
A382: 381 | B382: muktāhāreṇa | C382: ṣaṣṭhī- | D382: tatpuruṣa | E382: 6.62
A383: 382 | B383: sītāvalokane | C383: dvitīyā- | D383: tatpuruṣa | E383: 6.62
A384: 383 | B384: putravatsalā | C384: ṣaṣṭhī- | D384: tatpuruṣa | E384: 6.63
A385: 384 | B385: vastracandanakuṅkumaiḥ | C385: itaretara- | D385: dvandva | E385: 6.63
A386: 385 | B386: rāmājñayā | C386: ṣaṣṭhī- | D386: tatpuruṣa | E386: 6.64
A387: 386 | B387: sugrīvādiplavaṅgamāḥ | C387: viśeṣaṇapūrvapadaḥ | D387: karmadhāraya | E387: 6.64
A388: 387 | B388: sugrīvādi | C388: samānādhikaraṇa | D388: bahuvrīhi | E388: 6.64
A389: 388 | B389: śrīrāmavirahāturāḥ | C389: tṛtīyā- | D389: tatpuruṣa | E389: 6.64
A390: 389 | B390: śrīrāmavirahā | C390: ṣaṣṭhī- | D390: tatpuruṣa | E390: 6.64
A391: 390 | B391: śrīrāma | C391: viśeṣaṇapūrvapadaḥ | D391: karmadhāraya | E391: 6.64
...

Sheet По алфавиту
A1: Номер п.п. | B1: Алф_номер | C1: Самаса | D1: Подтип | E1: Тип | F1: Шлока | G1: Повтор самасы
A2: 248 | B2: 1 | C2: akṣādīni | D2: =VLOOKUP($A2,'По порядку'!$A$2:$E$414,3,FALSE) -> samānādhikaraṇa | E2: =VLOOKUP($A2,'По порядку'!$A$2:$E$414,4,FALSE) -> bahuvrīhi | F2: =VLOOKUP($A2,'По порядку'!$A$2:$E$414,5,FALSE) -> 5.11
A3: 135 | B3: 2 | C3: agastyasyāśramam | D3: =VLOOKUP($A3,'По порядку'!$A$2:$E$414,3,FALSE) -> ṣaṣṭhī- | E3: =VLOOKUP($A3,'По порядку'!$A$2:$E$414,4,FALSE) -> tatpuruṣa | F3: =VLOOKUP($A3,'По порядку'!$A$2:$E$414,5,FALSE) -> 3.3
A4: 346 | B4: 3 | C4: agnivacanāt | D4: =VLOOKUP($A4,'По порядку'!$A$2:$E$414,3,FALSE) -> ṣaṣṭhī- | E4: =VLOOKUP($A4,'По порядку'!$A$2:$E$414,4,FALSE) -> tatpuruṣa | F4: =VLOOKUP($A4,'По порядку'!$A$2:$E$414,5,FALSE) -> 6.48
A5: 227 | B5: 4 | C5: aṅgadādyāḥ | D5: =VLOOKUP($A5,'По порядку'!$A$2:$E$414,3,FALSE) -> samānādhikaraṇa- | E5: =VLOOKUP($A5,'По порядку'!$A$2:$E$414,4,FALSE) -> bahuvrīhi | F5: =VLOOKUP($A5,'По порядку'!$A$2:$E$414,5,FALSE) -> 4.19
A6: 402 | B6: 5 | C6: ajñajana | D6: =VLOOKUP($A6,'По порядку'!$A$2:$E$414,3,FALSE) -> viśeṣaṇapūrvapadaḥ | E6: =VLOOKUP($A6,'По порядку'!$A$2:$E$414,4,FALSE) -> karmadhāraya | F6: =VLOOKUP($A6,'По порядку'!$A$2:$E$414,5,FALSE) -> 7.1
A7: 401 | B7: 6 | C7: ajñajanavādena | D7: =VLOOKUP($A7,'По порядку'!$A$2:$E$414,3,FALSE) -> ṣaṣṭhī- | E7: =VLOOKUP($A7,'По порядку'!$A$2:$E$414,4,FALSE) -> tatpuruṣa | F7: =VLOOKUP($A7,'По порядку'!$A$2:$E$414,5,FALSE) -> 7.1
A8: 232 | B8: 7 | C8: anilātmajaḥ | D8: =VLOOKUP($A8,'По порядку'!$A$2:$E$414,3,FALSE) -> ṣaṣṭhī- | E8: =VLOOKUP($A8,'По порядку'!$A$2:$E$414,4,FALSE) -> tatpuruṣa | F8: =VLOOKUP($A8,'По порядку'!$A$2:$E$414,5,FALSE) -> 4.20
A9: 238 | B9: 8 | C9: anilātmajaḥ | D9: =VLOOKUP($A9,'По порядку'!$A$2:$E$414,3,FALSE) -> ṣaṣṭhī- | E9: =VLOOKUP($A9,'По порядку'!$A$2:$E$414,4,FALSE) -> tatpuruṣa | F9: =VLOOKUP($A9,'По порядку'!$A$2:$E$414,5,FALSE) -> 5.3 | G9: TRUE
A10: 359 | B10: 9 | C10: anuja | D10: =VLOOKUP($A10,'По порядку'!$A$2:$E$414,3,FALSE) -> upapada- | E10: =VLOOKUP($A10,'По порядку'!$A$2:$E$414,4,FALSE) -> tatpuruṣa | F10: =VLOOKUP($A10,'По порядку'!$A$2:$E$414,5,FALSE) -> 6.52
A11: 367 | B11: 10 | C11: anujaḥ | D11: =VLOOKUP($A11,'По порядку'!$A$2:$E$414,3,FALSE) -> upapada- | E11: =VLOOKUP($A11,'По порядку'!$A$2:$E$414,4,FALSE) -> tatpuruṣa | F11: =VLOOKUP($A11,'По порядку'!$A$2:$E$414,5,FALSE) -> 6.56
A12: 310 | B12: 11 | C12: anujena | D12: =VLOOKUP($A12,'По порядку'!$A$2:$E$414,3,FALSE) -> upapada- | E12: =VLOOKUP($A12,'По порядку'!$A$2:$E$414,4,FALSE) -> tatpuruṣa | F12: =VLOOKUP($A12,'По порядку'!$A$2:$E$414,5,FALSE) -> 6.27
A13: 173 | B13: 12 | C13: anujeritām | D13: =VLOOKUP($A13,'По порядку'!$A$2:$E$414,3,FALSE) -> ṣaṣṭhī- | E13: =VLOOKUP($A13,'По порядку'!$A$2:$E$414,4,FALSE) -> tatpuruṣa | F13: =VLOOKUP($A13,'По порядку'!$A$2:$E$414,5,FALSE) -> 3.22
A14: 376 | B14: 13 | C14: abhiṣekotsave | D14: =VLOOKUP($A14,'По порядку'!$A$2:$E$414,3,FALSE) -> viśeṣaṇapūrvapadaḥ | E14: =VLOOKUP($A14,'По порядку'!$A$2:$E$414,4,FALSE) -> karmadhāraya | F14: =VLOOKUP($A14,'По порядку'!$A$2:$E$414,5,FALSE) -> 6.61
A15: 327 | B15: 14 | C15: amarādhipam | D15: =VLOOKUP($A15,'По порядку'!$A$2:$E$414,3,FALSE) -> ṣaṣṭhī- | E15: =VLOOKUP($A15,'По порядку'!$A$2:$E$414,4,FALSE) -> tatpuruṣa | F15: =VLOOKUP($A15,'По порядку'!$A$2:$E$414,5,FALSE) -> 6.35
A16: 53 | B16: 15 | C16: ambhoja | D16: =VLOOKUP($A16,'По порядку'!$A$2:$E$414,3,FALSE) -> upapada- | E16: =VLOOKUP($A16,'По порядку'!$A$2:$E$414,4,FALSE) -> tatpuruṣa | F16: =VLOOKUP($A16,'По порядку'!$A$2:$E$414,5,FALSE) -> 1.26
A17: 373 | B17: 16 | C17: ayodhyānivāsāḥ | D17: =VLOOKUP($A17,'По порядку'!$A$2:$E$414,3,FALSE) -> samānādhikaraṇa | E17: =VLOOKUP($A17,'По порядку'!$A$2:$E$414,4,FALSE) -> bahuvrīhi | F17: =VLOOKUP($A17,'По порядку'!$A$2:$E$414,5,FALSE) -> 6.58
A18: 182 | B18: 17 | C18: ayomukhīm | D18: =VLOOKUP($A18,'По порядку'!$A$2:$E$414,3,FALSE) -> samānādhikaraṇa- | E18: =VLOOKUP($A18,'По порядку'!$A$2:$E$414,4,FALSE) -> bahuvrīhi | F18: =VLOOKUP($A18,'По порядку'!$A$2:$E$414,5,FALSE) -> 3.25
A19: 372 | B19: 18 | C19: arighātinā | D19: =VLOOKUP($A19,'По порядку'!$A$2:$E$414,3,FALSE) -> ṣaṣṭhī- | E19: =VLOOKUP($A19,'По порядку'!$A$2:$E$414,4,FALSE) -> tatpuruṣa | F19: =VLOOKUP($A19,'По порядку'!$A$2:$E$414,5,FALSE) -> 6.57
A20: 260 | B20: 19 | C20: arimardanaḥ | D20: =VLOOKUP($A20,'По порядку'!$A$2:$E$414,3,FALSE) -> dvitīyā- | E20: =VLOOKUP($A20,'По порядку'!$A$2:$E$414,4,FALSE) -> tatpuruṣa | F20: =VLOOKUP($A20,'По порядку'!$A$2:$E$414,5,FALSE) -> 6.2
A21: 169 | B21: 20 | C21: aśokavanikā | D21: =VLOOKUP($A21,'По порядку'!$A$2:$E$414,3,FALSE) -> viśeṣaṇapūrvapadaḥ | E21: =VLOOKUP($A21,'По порядку'!$A$2:$E$414,4,FALSE) -> karmadhāraya | F21: =VLOOKUP($A21,'По порядку'!$A$2:$E$414,5,FALSE) -> 3.21
... A27: 292 | B27: 26 | C27: ātmajaḥ | D27: =VLOOKUP($A27,'По порядку'!$A$2:$E$414,3,FALSE) -> upapada- | E27: =VLOOKUP($A27,'По порядку'!$A$2:$E$414,4,FALSE) -> tatpuruṣa | F27: =VLOOKUP($A27,'По порядку'!$A$2:$E$414,5,FALSE) -> 6.16
A28: 233 | B28: 27 | C28: ātmajaḥ | D28: =VLOOKUP($A28,'По порядку'!$A$2:$E$414,3,FALSE) -> upapada- | E28: =VLOOKUP($A28,'По порядку'!$A$2:$E$414,4,FALSE) -> tatpuruṣa | F28: =VLOOKUP($A28,'По порядку'!$A$2:$E$414,5,FALSE) -> 4.20 | G28: TRUE
A29: 235 | B29: 28 | C29: ātmajaḥ | D29: =VLOOKUP($A29,'По порядку'!$A$2:$E$414,3,FALSE) -> upapada- | E29: =VLOOKUP($A29,'По порядку'!$A$2:$E$414,4,FALSE) -> tatpuruṣa | F29: =VLOOKUP($A29,'По порядку'!$A$2:$E$414,5,FALSE) -> 5.1 | G29: TRUE
A30: 239 | B30: 29 | C30: ātmajaḥ | D30: =VLOOKUP($A30,'По порядку'!$A$2:$E$414,3,FALSE) -> upapada- | E30: =VLOOKUP($A30,'По порядку'!$A$2:$E$414,4,FALSE) -> tatpuruṣa | F30: =VLOOKUP($A30,'По порядку'!$A$2:$E$414,5,FALSE) -> 5.3 | G30: TRUE
A31: 294 | B31: 30 | C31: ātmajam | D31: =VLOOKUP($A31,'По порядку'!$A$2:$E$414,3,FALSE) -> upapada- | E31: =VLOOKUP($A31,'По порядку'!$A$2:$E$414,4,FALSE) -> tatpuruṣa | F31: =VLOOKUP($A31,'По порядку'!$A$2:$E$414,5,FALSE) -> 6.17
A32: 406 | B32: 31 | C32: ātmajā | D32: =VLOOKUP($A32,'По порядку'!$A$2:$E$414,3,FALSE) -> upapada- | E32: =VLOOKUP($A32,'По порядку'!$A$2:$E$414,4,FALSE) -> tatpuruṣa | F32: =VLOOKUP($A32,'По порядку'!$A$2:$E$414,5,FALSE) -> 7.5
A33: 171 | B33: 32 | C33: ātmajām | D33: =VLOOKUP($A33,'По порядку'!$A$2:$E$414,3,FALSE) -> upapada- | E33: =VLOOKUP($A33,'По порядку'!$A$2:$E$414,4,FALSE) -> tatpuruṣa | F33: =VLOOKUP($A33,'По порядку'!$A$2:$E$414,5,FALSE) -> 3.21
A34: 22 | B34: 33 | C34: ātmajena | D34: =VLOOKUP($A34,'По порядку'!$A$2:$E$414,3,FALSE) -> upapada- | E34: =VLOOKUP($A34,'По порядку'!$A$2:$E$414,4,FALSE) -> tatpuruṣa | F34: =VLOOKUP($A34,'По порядку'!$A$2:$E$414,5,FALSE) -> 1.10
A35: 29 | B35: 34 | C35: ātmayoni | D35: =VLOOKUP($A35,'По порядку'!$A$2:$E$414,3,FALSE) -> samānādhikaraṇa- | E35: =VLOOKUP($A35,'По порядку'!$A$2:$E$414,4,FALSE) -> bahuvrīhi | F35: =VLOOKUP($A35,'По порядку'!$A$2:$E$414,5,FALSE) -> 1.16
A36: 34 | B36: 35 | C36: ātmāṃśa | D36: =VLOOKUP($A36,'По порядку'!$A$2:$E$414,3,FALSE) -> ṣaṣṭhī- | E36: =VLOOKUP($A36,'По порядку'!$A$2:$E$414,4,FALSE) -> tatpuruṣa | F36: =VLOOKUP($A36,'По порядку'!$A$2:$E$414,5,FALSE) -> 1.17
A37: 216 | B37: 36 | C37: āśritavatsalaḥ | D37: =VLOOKUP($A37,'По порядку'!$A$2:$E$414,3,FALSE) -> ṣaṣṭhī- | E37: =VLOOKUP($A37,'По порядку'!$A$2:$E$414,4,FALSE) -> tatpuruṣa | F37: =VLOOKUP($A37,'По порядку'!$A$2:$E$414,5,FALSE) -> 4.12
A38: 10 | B38: 37 | C38: āśritavatsalāt | D38: =VLOOKUP($A38,'По порядку'!$A$2:$E$414,3,FALSE) -> ṣaṣṭhī- | E38: =VLOOKUP($A38,'По порядку'!$A$2:$E$414,4,FALSE) -> tatpuruṣa | F38: =VLOOKUP($A38,'По порядку'!$A$2:$E$414,5,FALSE) -> 1.3
A39: 312 | B39: 38 | C39: indrajit | D39: =VLOOKUP($A39,'По порядку'!$A$2:$E$414,3,FALSE) -> upapada- | E39: =VLOOKUP($A39,'По порядку'!$A$2:$E$414,4,FALSE) -> tatpuruṣa | F39: =VLOOKUP($A39,'По порядку'!$A$2:$E$414,5,FALSE) -> 6.28
A40: 297 | B40: 39 | C40: indrajit | D40: =VLOOKUP($A40,'По порядку'!$A$2:$E$414,3,FALSE) -> upapada- | E40: =VLOOKUP($A40,'По порядку'!$A$2:$E$414,4,FALSE) -> tatpuruṣa | F40: =VLOOKUP($A40,'По порядку'!$A$2:$E$414,5,FALSE) -> 6.19 | G40: TRUE
A41: 323 | B41: 40 | C41: indrajitam | D41: =VLOOKUP($A41,'По порядку'!$A$2:$E$414,3,FALSE) -> upapada- | E41: =VLOOKUP($A41,'По порядку'!$A$2:$E$414,4,FALSE) -> tatpuruṣa | F41: =VLOOKUP($A41,'По порядку'!$A$2:$E$414,5,FALSE) -> 6.32
A42: 181 | B42: 41 | C42: udakakriyām | D42: =VLOOKUP($A42,'По порядку'!$A$2:$E$414,3,FALSE) -> ṣaṣṭhī- | E42: =VLOOKUP($A42,'По порядку'!$A$2:$E$414,4,FALSE) -> tatpuruṣa | F42: =VLOOKUP($A42,'По порядку'!$A$2:$E$414,5,FALSE) -> 3.24
A43: 356 | B43: 42 | C43: udāradhīḥ | D43: =VLOOKUP($A43,'По порядку'!$A$2:$E$414,3,FALSE) -> samānādhikaraṇa | E43: =VLOOKUP($A43,'По порядку'!$A$2:$E$414,4,FALSE) -> bahuvrīhi | F43: =VLOOKUP($A43,'По порядку'!$A$2:$E$414,5,FALSE) -> 6.51
A44: 82 | B44: 43 | C44: urumānitaḥ | D44: =VLOOKUP($A44,'По порядку'!$A$2:$E$414,3,FALSE) -> viśeṣaṇapūrvapadaḥ | E44: =VLOOKUP($A44,'По порядку'!$A$2:$E$414,4,FALSE) -> karmadhāraya | F44: =VLOOKUP($A44,'По порядку'!$A$2:$E$414,5,FALSE) -> 1.38
A45: 188 | B45: 44 | C45: ṛṣyamūkastham | D45: =VLOOKUP($A45,'По порядку'!$A$2:$E$414,3,FALSE) -> upapada- | E45: =VLOOKUP($A45,'По порядку'!$A$2:$E$414,4,FALSE) -> tatpuruṣa | F45: =VLOOKUP($A45,'По порядку'!$A$2:$E$414,5,FALSE) -> 3.27
...

Sheet По группам
A1: Алф_Номер | B1: Самаса | C1: Подтип | D1: Тип | E1: Шлока
A2: 213 | B2: yathārham | C2: nitya? | D2: avyayībhāva | E2: 6.61
A3: 214 | B3: yathāvidhi | C3: nitya? | D3: avyayībhāva | E3: 2.14
A4: 328 | B4: sadārānujam | C4: saha- | D4: bahuvrīhi | E4: 3.1
A5: 344 | B5: salakṣmaṇaḥ | C5: saha- | D5: bahuvrīhi | E5: 3.28
A6: 354 | B6: sahānujaḥ | C6: saha- | D6: bahuvrīhi | E6: 3.24
A7: 355 | B7: sahānujaḥ | C7: saha- | D7: bahuvrīhi | E7: 3.23
A8: 350 | B8: sahānugam | C8: sahapūrvapado | D8: bahuvrīhi | E8: 3.11
A9: 329 | B9: sapurohitaḥ | C9: sahapūrvapado | D9: bahuvrīhi | E9: 1.23
A10: 332 | B10: sabhāryāḥ | C10: sahapūrvapado | D10: bahuvrīhi | E10: 6.68
A11: 333 | B11: samantriṇā | C11: sahapūrvapado | D11: bahuvrīhi | E11: 6.26
A12: 345 | B12: salakṣmaṇam | C12: sahapūrvapado | D12: bahuvrīhi | E12: 6.41
A13: 346 | B13: savibhīṣaṇaḥ | C13: sahapūrvapado | D13: bahuvrīhi | E13: 6.28
... A414: 371 | B414: sītāharaṇajāt | C414: upapada- | D414: tatpuruṣa | E414: 6.44

Sheet По группам всего
A1: Подтип | B1: Тип | C1: Кол-во | D1: Сокр. | F1: Длинное сокращение
A2: ṣaṣṭhī- | B2: tatpuruṣa | C2: 129 | D2: T6 | F2: ṣaṣṭhī-tat.
A3: upapada- | B3: tatpuruṣa | C3: 40 | D3: U | F3: upapada-tat.
A4: tṛtīyā- | B4: tatpuruṣa | C4: 35 | D4: T3 | F4: tṛtīyā-tat.
A5: saptamī- | B5: tatpuruṣa | C5: 11 | D5: T7 | F5: saptamī-tat.
A6: prādi- | B6: tatpuruṣa | C6: 10 | D6: Tp | F6: prādi-tat.
A7: dvitīyā- | B7: tatpuruṣa | C7: 7 | D7: T2 | F7: dvitīyā-tat.
A8: pañcamī- | B8: tatpuruṣa | C8: 3 | D8: T5 | F8: pañcamī-tat.
A9: caturthī- | B9: tatpuruṣa | C9: 2 | D9: T4 | F9: caturthī-tat.
A10: nañ- | B10: tatpuruṣa | C10: 1 | D10: Tn | F10: nañ-tat.
A11: viśeṣaṇapūrvapadaḥ | B11: karmadhāraya | C11: 40 | D11: K1 | F11: viśeṣaṇa. karmadhā.
A12: upamānapūrvapadaḥ | B12: karmadhāraya | C12: 2 | D12: K4 | F12: upamānapū. karma.
A13: upamānottarapadaḥ | B13: karmadhāraya | C13: 2 | D13: K5 | F13: upamānotta. karma.
A14: samānādhikaraṇa- | B14: bahuvrīhi | C14: 87 | D14: Bs? | E14: Тоже есть подвиды | F14: samānādhi-bah.
A15: sahapūrvapado | B15: bahuvrīhi | C15: 13 | D15: BvS | E15: vyadhikaraṇa-? Тогда почему vyadhikaraṇa- отдельно?
A16: saha- | B16: bahuvrīhi | C16: 4 | D16: Тоже sahapūrvapado ? Других saha-bahuvrīhi просто нет. | F16: saha-bah.
A17: vyadhikaraṇa- | B17: bahuvrīhi | C17: 4 | D17: Bv? | E17: Тоже есть подвиды | F17: vyadhi-bah.
A18: itaretara- | B18: dvandva | C18: 20 | D18: Di | F18: itaretara-dva.
A19: samāhāra- | B19: dvandva | C19: 1 | D19: Ds | F19: samāhāra-dva.
B20: avyayībhāva | C20: 2 | D20: A | E20: Какая из? Их 7 видов? | F20: avyayībhāva
